[2025-03-18 02:20:14 UTC] Step ingest_df has started.

[2025-03-18 02:20:14 UTC] Ingesting Data from C:Users\USER\Desktop\interview_package\data\interview_dataset.csv

[2025-03-18 02:20:14 UTC] Error while ingesting data [Errno 2] No such file or directory: 'C:Users\\USER\\Desktop\\interview_package\\data\\interview_dataset.csv'

[2025-03-18 02:20:14 UTC] Failed to run step ingest_df after 1 retries. Exiting.

[2025-03-18 02:20:14 UTC] [Errno 2] No such file or directory: 'C:Users\\USER\\Desktop\\interview_package\\data\\interview_dataset.csv'
Traceback (most recent call last):
  File "C:\Users\USER\AppData\Local\Packages\PythonSoftwareFoundation.Python.3.9_qbz5n2kfra8p0\LocalCache\local-packages\Python39\site-packages\zenml\orchestrators\step_launcher.py", line 255, in launch
    self._run_step(
  File "C:\Users\USER\AppData\Local\Packages\PythonSoftwareFoundation.Python.3.9_qbz5n2kfra8p0\LocalCache\local-packages\Python39\site-packages\zenml\orchestrators\step_launcher.py", line 377, in _run_step
    self._run_step_without_step_operator(
  File "C:\Users\USER\AppData\Local\Packages\PythonSoftwareFoundation.Python.3.9_qbz5n2kfra8p0\LocalCache\local-packages\Python39\site-packages\zenml\orchestrators\step_launcher.py", line 462, in _run_step_without_step_operator
    runner.run(
  File "C:\Users\USER\AppData\Local\Packages\PythonSoftwareFoundation.Python.3.9_qbz5n2kfra8p0\LocalCache\local-packages\Python39\site-packages\zenml\orchestrators\step_runner.py", line 187, in run
    return_values = step_instance.call_entrypoint(
  File "C:\Users\USER\AppData\Local\Packages\PythonSoftwareFoundation.Python.3.9_qbz5n2kfra8p0\LocalCache\local-packages\Python39\site-packages\zenml\steps\base_step.py", line 554, in call_entrypoint
    return self.entrypoint(**validated_args)
  File "C:\Users\USER\Desktop\interview_package\steps\ingest_data.py", line 39, in ingest_df
    raise e
  File "C:\Users\USER\Desktop\interview_package\steps\ingest_data.py", line 35, in ingest_df
    df = ingest_data_instance.get_data()  # Call get_data on the instance
  File "C:\Users\USER\Desktop\interview_package\steps\ingest_data.py", line 21, in get_data
    return pd.read_csv(self.data_path)
  File "C:\Users\USER\AppData\Local\Packages\PythonSoftwareFoundation.Python.3.9_qbz5n2kfra8p0\LocalCache\local-packages\Python39\site-packages\pandas\io\parsers\readers.py", line 1026, in read_csv
    return _read(filepath_or_buffer, kwds)
  File "C:\Users\USER\AppData\Local\Packages\PythonSoftwareFoundation.Python.3.9_qbz5n2kfra8p0\LocalCache\local-packages\Python39\site-packages\pandas\io\parsers\readers.py", line 620, in _read
    parser = TextFileReader(filepath_or_buffer, **kwds)
  File "C:\Users\USER\AppData\Local\Packages\PythonSoftwareFoundation.Python.3.9_qbz5n2kfra8p0\LocalCache\local-packages\Python39\site-packages\pandas\io\parsers\readers.py", line 1620, in __init__
    self._engine = self._make_engine(f, self.engine)
  File "C:\Users\USER\AppData\Local\Packages\PythonSoftwareFoundation.Python.3.9_qbz5n2kfra8p0\LocalCache\local-packages\Python39\site-packages\pandas\io\parsers\readers.py", line 1880, in _make_engine
    self.handles = get_handle(
  File "C:\Users\USER\AppData\Local\Packages\PythonSoftwareFoundation.Python.3.9_qbz5n2kfra8p0\LocalCache\local-packages\Python39\site-packages\pandas\io\common.py", line 873, in get_handle
    handle = open(
FileNotFoundError: [Errno 2] No such file or directory: 'C:Users\\USER\\Desktop\\interview_package\\data\\interview_dataset.csv'

